[2023-12-25T02:24:39.098+0000] {taskinstance.py:1957} INFO - Dependencies all met for dep_context=non-requeueable deps ti=<TaskInstance: traffic_flow.Extract scheduled__2023-01-22T00:00:00+00:00 [queued]>
[2023-12-25T02:24:39.123+0000] {taskinstance.py:1957} INFO - Dependencies all met for dep_context=requeueable deps ti=<TaskInstance: traffic_flow.Extract scheduled__2023-01-22T00:00:00+00:00 [queued]>
[2023-12-25T02:24:39.123+0000] {taskinstance.py:2171} INFO - Starting attempt 1 of 2
[2023-12-25T02:24:39.195+0000] {taskinstance.py:2192} INFO - Executing <Task(PythonOperator): Extract> on 2023-01-22 00:00:00+00:00
[2023-12-25T02:24:39.205+0000] {standard_task_runner.py:60} INFO - Started process 10771 to run task
[2023-12-25T02:24:39.227+0000] {standard_task_runner.py:87} INFO - Running: ['***', 'tasks', 'run', 'traffic_flow', 'Extract', 'scheduled__2023-01-22T00:00:00+00:00', '--job-id', '27', '--raw', '--subdir', 'DAGS_FOLDER/main.py', '--cfg-path', '/tmp/tmp_w59blmw']
[2023-12-25T02:24:39.230+0000] {standard_task_runner.py:88} INFO - Job 27: Subtask Extract
[2023-12-25T02:24:39.303+0000] {logging_mixin.py:188} WARNING - /home/***/.local/lib/python3.8/site-packages/***/settings.py:195 DeprecationWarning: The sql_alchemy_conn option in [core] has been moved to the sql_alchemy_conn option in [database] - the old setting has been used, but please update your config.
[2023-12-25T02:24:39.422+0000] {task_command.py:423} INFO - Running <TaskInstance: traffic_flow.Extract scheduled__2023-01-22T00:00:00+00:00 [running]> on host 9f4b92a38ae3
[2023-12-25T02:24:39.763+0000] {taskinstance.py:2481} INFO - Exporting env vars: AIRFLOW_CTX_DAG_OWNER='***' AIRFLOW_CTX_DAG_ID='traffic_flow' AIRFLOW_CTX_TASK_ID='Extract' AIRFLOW_CTX_EXECUTION_DATE='2023-01-22T00:00:00+00:00' AIRFLOW_CTX_TRY_NUMBER='1' AIRFLOW_CTX_DAG_RUN_ID='scheduled__2023-01-22T00:00:00+00:00'
[2023-12-25T02:24:39.765+0000] {taskinstance.py:2699} ERROR - Task failed with exception
Traceback (most recent call last):
  File "/home/airflow/.local/lib/python3.8/site-packages/airflow/models/taskinstance.py", line 433, in _execute_task
    result = execute_callable(context=context, **execute_callable_kwargs)
  File "/home/airflow/.local/lib/python3.8/site-packages/airflow/operators/python.py", line 199, in execute
    return_value = self.execute_callable()
  File "/home/airflow/.local/lib/python3.8/site-packages/airflow/operators/python.py", line 216, in execute_callable
    return self.python_callable(*self.op_args, **self.op_kwargs)
  File "/opt/airflow/dags/main.py", line 31, in task_a_function
    csv_reader.read_data()
  File "/opt/airflow/dags/src/extract_data_source.py", line 10, in read_data
    with open(self.csv_path, 'r') as file:
FileNotFoundError: [Errno 2] No such file or directory: '/home/hp/Downloads/20181024_d1_0830_0900(2).csv'
[2023-12-25T02:24:39.790+0000] {taskinstance.py:1138} INFO - Marking task as UP_FOR_RETRY. dag_id=traffic_flow, task_id=Extract, execution_date=20230122T000000, start_date=20231225T022439, end_date=20231225T022439
[2023-12-25T02:24:40.688+0000] {standard_task_runner.py:107} ERROR - Failed to execute job 27 for task Extract ([Errno 2] No such file or directory: '/home/hp/Downloads/20181024_d1_0830_0900(2).csv'; 10771)
[2023-12-25T02:24:40.719+0000] {local_task_job_runner.py:234} INFO - Task exited with return code 1
[2023-12-25T02:24:40.775+0000] {taskinstance.py:3281} INFO - 0 downstream tasks scheduled from follow-on schedule check
[2023-12-25T07:40:04.036+0000] {logging_mixin.py:188} INFO - Changing /opt/***/logs/dag_id=traffic_flow/run_id=scheduled__2023-01-22T00:00:00+00:00/task_id=Extract permission to 509
[2023-12-25T07:40:04.040+0000] {logging_mixin.py:188} INFO - Failed to change /opt/***/logs/dag_id=traffic_flow/run_id=scheduled__2023-01-22T00:00:00+00:00/task_id=Extract permission to 509: [Errno 1] Operation not permitted: '/opt/***/logs/dag_id=traffic_flow/run_id=scheduled__2023-01-22T00:00:00+00:00/task_id=Extract'
[2023-12-25T07:40:04.529+0000] {logging_mixin.py:188} INFO - Changing /opt/***/logs/dag_id=traffic_flow/run_id=scheduled__2023-01-22T00:00:00+00:00/task_id=Extract permission to 509
[2023-12-25T07:40:04.529+0000] {logging_mixin.py:188} INFO - Failed to change /opt/***/logs/dag_id=traffic_flow/run_id=scheduled__2023-01-22T00:00:00+00:00/task_id=Extract permission to 509: [Errno 1] Operation not permitted: '/opt/***/logs/dag_id=traffic_flow/run_id=scheduled__2023-01-22T00:00:00+00:00/task_id=Extract'
[2023-12-25T07:40:05.572+0000] {taskinstance.py:1957} INFO - Dependencies all met for dep_context=non-requeueable deps ti=<TaskInstance: traffic_flow.Extract scheduled__2023-01-22T00:00:00+00:00 [queued]>
[2023-12-25T07:40:05.651+0000] {taskinstance.py:1957} INFO - Dependencies all met for dep_context=requeueable deps ti=<TaskInstance: traffic_flow.Extract scheduled__2023-01-22T00:00:00+00:00 [queued]>
[2023-12-25T07:40:05.652+0000] {taskinstance.py:2171} INFO - Starting attempt 1 of 2
[2023-12-25T07:40:05.806+0000] {taskinstance.py:2192} INFO - Executing <Task(PythonOperator): Extract> on 2023-01-22 00:00:00+00:00
[2023-12-25T07:40:05.831+0000] {standard_task_runner.py:60} INFO - Started process 433 to run task
[2023-12-25T07:40:05.844+0000] {standard_task_runner.py:87} INFO - Running: ['***', 'tasks', 'run', 'traffic_flow', 'Extract', 'scheduled__2023-01-22T00:00:00+00:00', '--job-id', '42', '--raw', '--subdir', 'DAGS_FOLDER/main.py', '--cfg-path', '/tmp/tmp5kl35h48']
[2023-12-25T07:40:05.851+0000] {standard_task_runner.py:88} INFO - Job 42: Subtask Extract
[2023-12-25T07:40:06.210+0000] {logging_mixin.py:188} WARNING - /home/***/.local/lib/python3.8/site-packages/***/settings.py:195 DeprecationWarning: The sql_alchemy_conn option in [core] has been moved to the sql_alchemy_conn option in [database] - the old setting has been used, but please update your config.
[2023-12-25T07:40:06.889+0000] {logging_mixin.py:188} INFO - Changing /opt/***/logs/dag_id=traffic_flow/run_id=scheduled__2023-01-22T00:00:00+00:00/task_id=Extract permission to 509
[2023-12-25T07:40:06.890+0000] {logging_mixin.py:188} INFO - Failed to change /opt/***/logs/dag_id=traffic_flow/run_id=scheduled__2023-01-22T00:00:00+00:00/task_id=Extract permission to 509: [Errno 1] Operation not permitted: '/opt/***/logs/dag_id=traffic_flow/run_id=scheduled__2023-01-22T00:00:00+00:00/task_id=Extract'
[2023-12-25T07:40:06.900+0000] {task_command.py:423} INFO - Running <TaskInstance: traffic_flow.Extract scheduled__2023-01-22T00:00:00+00:00 [running]> on host b33131cfaa7f
[2023-12-25T07:40:07.354+0000] {taskinstance.py:2481} INFO - Exporting env vars: AIRFLOW_CTX_DAG_OWNER='***' AIRFLOW_CTX_DAG_ID='traffic_flow' AIRFLOW_CTX_TASK_ID='Extract' AIRFLOW_CTX_EXECUTION_DATE='2023-01-22T00:00:00+00:00' AIRFLOW_CTX_TRY_NUMBER='1' AIRFLOW_CTX_DAG_RUN_ID='scheduled__2023-01-22T00:00:00+00:00'
[2023-12-25T07:40:07.356+0000] {taskinstance.py:2699} ERROR - Task failed with exception
Traceback (most recent call last):
  File "/home/airflow/.local/lib/python3.8/site-packages/airflow/models/taskinstance.py", line 433, in _execute_task
    result = execute_callable(context=context, **execute_callable_kwargs)
  File "/home/airflow/.local/lib/python3.8/site-packages/airflow/operators/python.py", line 199, in execute
    return_value = self.execute_callable()
  File "/home/airflow/.local/lib/python3.8/site-packages/airflow/operators/python.py", line 216, in execute_callable
    return self.python_callable(*self.op_args, **self.op_kwargs)
  File "/opt/airflow/dags/main.py", line 31, in task_a_function
    csv_reader.read_data()
  File "/opt/airflow/dags/src/extract_data_source.py", line 10, in read_data
    with open(self.csv_path, 'r') as file:
FileNotFoundError: [Errno 2] No such file or directory: '/home/hp/Downloads/20181024_d1_0830_0900(2).csv'
[2023-12-25T07:40:07.405+0000] {taskinstance.py:1138} INFO - Marking task as UP_FOR_RETRY. dag_id=traffic_flow, task_id=Extract, execution_date=20230122T000000, start_date=20231225T074005, end_date=20231225T074007
[2023-12-25T07:40:10.955+0000] {standard_task_runner.py:107} ERROR - Failed to execute job 42 for task Extract ([Errno 2] No such file or directory: '/home/hp/Downloads/20181024_d1_0830_0900(2).csv'; 433)
[2023-12-25T07:40:11.027+0000] {local_task_job_runner.py:234} INFO - Task exited with return code 1
[2023-12-25T07:40:11.245+0000] {taskinstance.py:3281} INFO - 0 downstream tasks scheduled from follow-on schedule check
