[2023-12-25T02:18:35.546+0000] {taskinstance.py:1957} INFO - Dependencies all met for dep_context=non-requeueable deps ti=<TaskInstance: traffic_flow.Extract scheduled__2023-01-13T00:00:00+00:00 [queued]>
[2023-12-25T02:18:35.961+0000] {taskinstance.py:1957} INFO - Dependencies all met for dep_context=requeueable deps ti=<TaskInstance: traffic_flow.Extract scheduled__2023-01-13T00:00:00+00:00 [queued]>
[2023-12-25T02:18:35.963+0000] {taskinstance.py:2171} INFO - Starting attempt 1 of 2
[2023-12-25T02:18:36.371+0000] {taskinstance.py:2192} INFO - Executing <Task(PythonOperator): Extract> on 2023-01-13 00:00:00+00:00
[2023-12-25T02:18:36.387+0000] {standard_task_runner.py:60} INFO - Started process 9440 to run task
[2023-12-25T02:18:36.398+0000] {standard_task_runner.py:87} INFO - Running: ['***', 'tasks', 'run', 'traffic_flow', 'Extract', 'scheduled__2023-01-13T00:00:00+00:00', '--job-id', '4', '--raw', '--subdir', 'DAGS_FOLDER/main.py', '--cfg-path', '/tmp/tmp33kib9b1']
[2023-12-25T02:18:36.403+0000] {standard_task_runner.py:88} INFO - Job 4: Subtask Extract
[2023-12-25T02:18:36.756+0000] {logging_mixin.py:188} WARNING - /home/***/.local/lib/python3.8/site-packages/***/settings.py:195 DeprecationWarning: The sql_alchemy_conn option in [core] has been moved to the sql_alchemy_conn option in [database] - the old setting has been used, but please update your config.
[2023-12-25T02:18:36.905+0000] {task_command.py:423} INFO - Running <TaskInstance: traffic_flow.Extract scheduled__2023-01-13T00:00:00+00:00 [running]> on host 9f4b92a38ae3
[2023-12-25T02:18:38.987+0000] {taskinstance.py:2481} INFO - Exporting env vars: AIRFLOW_CTX_DAG_OWNER='***' AIRFLOW_CTX_DAG_ID='traffic_flow' AIRFLOW_CTX_TASK_ID='Extract' AIRFLOW_CTX_EXECUTION_DATE='2023-01-13T00:00:00+00:00' AIRFLOW_CTX_TRY_NUMBER='1' AIRFLOW_CTX_DAG_RUN_ID='scheduled__2023-01-13T00:00:00+00:00'
[2023-12-25T02:18:39.121+0000] {taskinstance.py:2699} ERROR - Task failed with exception
Traceback (most recent call last):
  File "/home/airflow/.local/lib/python3.8/site-packages/airflow/models/taskinstance.py", line 433, in _execute_task
    result = execute_callable(context=context, **execute_callable_kwargs)
  File "/home/airflow/.local/lib/python3.8/site-packages/airflow/operators/python.py", line 199, in execute
    return_value = self.execute_callable()
  File "/home/airflow/.local/lib/python3.8/site-packages/airflow/operators/python.py", line 216, in execute_callable
    return self.python_callable(*self.op_args, **self.op_kwargs)
  File "/opt/airflow/dags/main.py", line 31, in task_a_function
    csv_reader.read_data()
  File "/opt/airflow/dags/src/extract_data_source.py", line 10, in read_data
    with open(self.csv_path, 'r') as file:
FileNotFoundError: [Errno 2] No such file or directory: '/home/hp/Downloads/20181024_d1_0830_0900(2).csv'
[2023-12-25T02:18:39.272+0000] {taskinstance.py:1138} INFO - Marking task as UP_FOR_RETRY. dag_id=traffic_flow, task_id=Extract, execution_date=20230113T000000, start_date=20231225T021835, end_date=20231225T021839
[2023-12-25T02:19:05.878+0000] {standard_task_runner.py:107} ERROR - Failed to execute job 4 for task Extract ([Errno 2] No such file or directory: '/home/hp/Downloads/20181024_d1_0830_0900(2).csv'; 9440)
[2023-12-25T02:19:05.951+0000] {local_task_job_runner.py:234} INFO - Task exited with return code 1
[2023-12-25T02:19:05.995+0000] {taskinstance.py:3281} INFO - 0 downstream tasks scheduled from follow-on schedule check
[2023-12-25T07:28:00.850+0000] {logging_mixin.py:188} INFO - Changing /opt/***/logs/dag_id=traffic_flow/run_id=scheduled__2023-01-13T00:00:00+00:00/task_id=Extract permission to 509
[2023-12-25T07:28:00.936+0000] {logging_mixin.py:188} INFO - Failed to change /opt/***/logs/dag_id=traffic_flow/run_id=scheduled__2023-01-13T00:00:00+00:00/task_id=Extract permission to 509: [Errno 1] Operation not permitted: '/opt/***/logs/dag_id=traffic_flow/run_id=scheduled__2023-01-13T00:00:00+00:00/task_id=Extract'
[2023-12-25T07:28:03.289+0000] {logging_mixin.py:188} INFO - Changing /opt/***/logs/dag_id=traffic_flow/run_id=scheduled__2023-01-13T00:00:00+00:00/task_id=Extract permission to 509
[2023-12-25T07:28:03.290+0000] {logging_mixin.py:188} INFO - Failed to change /opt/***/logs/dag_id=traffic_flow/run_id=scheduled__2023-01-13T00:00:00+00:00/task_id=Extract permission to 509: [Errno 1] Operation not permitted: '/opt/***/logs/dag_id=traffic_flow/run_id=scheduled__2023-01-13T00:00:00+00:00/task_id=Extract'
[2023-12-25T07:28:13.277+0000] {taskinstance.py:1957} INFO - Dependencies all met for dep_context=non-requeueable deps ti=<TaskInstance: traffic_flow.Extract scheduled__2023-01-13T00:00:00+00:00 [queued]>
[2023-12-25T07:28:13.607+0000] {taskinstance.py:1957} INFO - Dependencies all met for dep_context=requeueable deps ti=<TaskInstance: traffic_flow.Extract scheduled__2023-01-13T00:00:00+00:00 [queued]>
[2023-12-25T07:28:13.607+0000] {taskinstance.py:2171} INFO - Starting attempt 1 of 2
[2023-12-25T07:28:14.874+0000] {taskinstance.py:2192} INFO - Executing <Task(PythonOperator): Extract> on 2023-01-13 00:00:00+00:00
[2023-12-25T07:28:14.947+0000] {standard_task_runner.py:60} INFO - Started process 249 to run task
[2023-12-25T07:28:14.971+0000] {standard_task_runner.py:87} INFO - Running: ['***', 'tasks', 'run', 'traffic_flow', 'Extract', 'scheduled__2023-01-13T00:00:00+00:00', '--job-id', '14', '--raw', '--subdir', 'DAGS_FOLDER/main.py', '--cfg-path', '/tmp/tmpegn0ufbx']
[2023-12-25T07:28:14.976+0000] {standard_task_runner.py:88} INFO - Job 14: Subtask Extract
[2023-12-25T07:28:23.490+0000] {logging_mixin.py:188} WARNING - /home/***/.local/lib/python3.8/site-packages/***/settings.py:195 DeprecationWarning: The sql_alchemy_conn option in [core] has been moved to the sql_alchemy_conn option in [database] - the old setting has been used, but please update your config.
[2023-12-25T07:29:00.681+0000] {logging_mixin.py:188} INFO - Changing /opt/***/logs/dag_id=traffic_flow/run_id=scheduled__2023-01-13T00:00:00+00:00/task_id=Extract permission to 509
[2023-12-25T07:29:00.775+0000] {logging_mixin.py:188} INFO - Failed to change /opt/***/logs/dag_id=traffic_flow/run_id=scheduled__2023-01-13T00:00:00+00:00/task_id=Extract permission to 509: [Errno 1] Operation not permitted: '/opt/***/logs/dag_id=traffic_flow/run_id=scheduled__2023-01-13T00:00:00+00:00/task_id=Extract'
[2023-12-25T07:29:00.870+0000] {task_command.py:423} INFO - Running <TaskInstance: traffic_flow.Extract scheduled__2023-01-13T00:00:00+00:00 [running]> on host b33131cfaa7f
[2023-12-25T07:29:05.572+0000] {taskinstance.py:2481} INFO - Exporting env vars: AIRFLOW_CTX_DAG_OWNER='***' AIRFLOW_CTX_DAG_ID='traffic_flow' AIRFLOW_CTX_TASK_ID='Extract' AIRFLOW_CTX_EXECUTION_DATE='2023-01-13T00:00:00+00:00' AIRFLOW_CTX_TRY_NUMBER='1' AIRFLOW_CTX_DAG_RUN_ID='scheduled__2023-01-13T00:00:00+00:00'
[2023-12-25T07:29:05.913+0000] {taskinstance.py:2699} ERROR - Task failed with exception
Traceback (most recent call last):
  File "/home/airflow/.local/lib/python3.8/site-packages/airflow/models/taskinstance.py", line 433, in _execute_task
    result = execute_callable(context=context, **execute_callable_kwargs)
  File "/home/airflow/.local/lib/python3.8/site-packages/airflow/operators/python.py", line 199, in execute
    return_value = self.execute_callable()
  File "/home/airflow/.local/lib/python3.8/site-packages/airflow/operators/python.py", line 216, in execute_callable
    return self.python_callable(*self.op_args, **self.op_kwargs)
  File "/opt/airflow/dags/main.py", line 31, in task_a_function
    csv_reader.read_data()
  File "/opt/airflow/dags/src/extract_data_source.py", line 10, in read_data
    with open(self.csv_path, 'r') as file:
FileNotFoundError: [Errno 2] No such file or directory: '/home/hp/Downloads/20181024_d1_0830_0900(2).csv'
[2023-12-25T07:29:06.793+0000] {taskinstance.py:1138} INFO - Marking task as UP_FOR_RETRY. dag_id=traffic_flow, task_id=Extract, execution_date=20230113T000000, start_date=20231225T072813, end_date=20231225T072906
[2023-12-25T07:29:39.474+0000] {standard_task_runner.py:107} ERROR - Failed to execute job 14 for task Extract ([Errno 2] No such file or directory: '/home/hp/Downloads/20181024_d1_0830_0900(2).csv'; 249)
[2023-12-25T07:29:39.546+0000] {local_task_job_runner.py:234} INFO - Task exited with return code 1
[2023-12-25T07:29:40.016+0000] {taskinstance.py:3281} INFO - 0 downstream tasks scheduled from follow-on schedule check
