[2023-12-25T07:46:00.989+0000] {logging_mixin.py:188} INFO - Changing /opt/***/logs/dag_id=traffic_flow/run_id=scheduled__2023-02-15T00:00:00+00:00/task_id=Extract permission to 509
[2023-12-25T07:46:00.990+0000] {logging_mixin.py:188} INFO - Failed to change /opt/***/logs/dag_id=traffic_flow/run_id=scheduled__2023-02-15T00:00:00+00:00/task_id=Extract permission to 509: [Errno 1] Operation not permitted: '/opt/***/logs/dag_id=traffic_flow/run_id=scheduled__2023-02-15T00:00:00+00:00/task_id=Extract'
[2023-12-25T07:46:01.120+0000] {logging_mixin.py:188} INFO - Changing /opt/***/logs/dag_id=traffic_flow/run_id=scheduled__2023-02-15T00:00:00+00:00/task_id=Extract permission to 509
[2023-12-25T07:46:01.120+0000] {logging_mixin.py:188} INFO - Failed to change /opt/***/logs/dag_id=traffic_flow/run_id=scheduled__2023-02-15T00:00:00+00:00/task_id=Extract permission to 509: [Errno 1] Operation not permitted: '/opt/***/logs/dag_id=traffic_flow/run_id=scheduled__2023-02-15T00:00:00+00:00/task_id=Extract'
[2023-12-25T07:46:01.232+0000] {taskinstance.py:1957} INFO - Dependencies all met for dep_context=non-requeueable deps ti=<TaskInstance: traffic_flow.Extract scheduled__2023-02-15T00:00:00+00:00 [queued]>
[2023-12-25T07:46:01.248+0000] {taskinstance.py:1957} INFO - Dependencies all met for dep_context=requeueable deps ti=<TaskInstance: traffic_flow.Extract scheduled__2023-02-15T00:00:00+00:00 [queued]>
[2023-12-25T07:46:01.249+0000] {taskinstance.py:2171} INFO - Starting attempt 1 of 2
[2023-12-25T07:46:01.291+0000] {taskinstance.py:2192} INFO - Executing <Task(PythonOperator): Extract> on 2023-02-15 00:00:00+00:00
[2023-12-25T07:46:01.300+0000] {standard_task_runner.py:60} INFO - Started process 603 to run task
[2023-12-25T07:46:01.311+0000] {standard_task_runner.py:87} INFO - Running: ['***', 'tasks', 'run', 'traffic_flow', 'Extract', 'scheduled__2023-02-15T00:00:00+00:00', '--job-id', '84', '--raw', '--subdir', 'DAGS_FOLDER/main.py', '--cfg-path', '/tmp/tmpzytflkjt']
[2023-12-25T07:46:01.316+0000] {standard_task_runner.py:88} INFO - Job 84: Subtask Extract
[2023-12-25T07:46:01.379+0000] {logging_mixin.py:188} WARNING - /home/***/.local/lib/python3.8/site-packages/***/settings.py:195 DeprecationWarning: The sql_alchemy_conn option in [core] has been moved to the sql_alchemy_conn option in [database] - the old setting has been used, but please update your config.
[2023-12-25T07:46:01.473+0000] {logging_mixin.py:188} INFO - Changing /opt/***/logs/dag_id=traffic_flow/run_id=scheduled__2023-02-15T00:00:00+00:00/task_id=Extract permission to 509
[2023-12-25T07:46:01.474+0000] {logging_mixin.py:188} INFO - Failed to change /opt/***/logs/dag_id=traffic_flow/run_id=scheduled__2023-02-15T00:00:00+00:00/task_id=Extract permission to 509: [Errno 1] Operation not permitted: '/opt/***/logs/dag_id=traffic_flow/run_id=scheduled__2023-02-15T00:00:00+00:00/task_id=Extract'
[2023-12-25T07:46:01.477+0000] {task_command.py:423} INFO - Running <TaskInstance: traffic_flow.Extract scheduled__2023-02-15T00:00:00+00:00 [running]> on host b33131cfaa7f
[2023-12-25T07:46:01.735+0000] {taskinstance.py:2481} INFO - Exporting env vars: AIRFLOW_CTX_DAG_OWNER='***' AIRFLOW_CTX_DAG_ID='traffic_flow' AIRFLOW_CTX_TASK_ID='Extract' AIRFLOW_CTX_EXECUTION_DATE='2023-02-15T00:00:00+00:00' AIRFLOW_CTX_TRY_NUMBER='1' AIRFLOW_CTX_DAG_RUN_ID='scheduled__2023-02-15T00:00:00+00:00'
[2023-12-25T07:46:01.737+0000] {taskinstance.py:2699} ERROR - Task failed with exception
Traceback (most recent call last):
  File "/home/airflow/.local/lib/python3.8/site-packages/airflow/models/taskinstance.py", line 433, in _execute_task
    result = execute_callable(context=context, **execute_callable_kwargs)
  File "/home/airflow/.local/lib/python3.8/site-packages/airflow/operators/python.py", line 199, in execute
    return_value = self.execute_callable()
  File "/home/airflow/.local/lib/python3.8/site-packages/airflow/operators/python.py", line 216, in execute_callable
    return self.python_callable(*self.op_args, **self.op_kwargs)
  File "/opt/airflow/dags/main.py", line 31, in task_a_function
    csv_reader.read_data()
  File "/opt/airflow/dags/src/extract_data_source.py", line 10, in read_data
    with open(self.csv_path, 'r') as file:
FileNotFoundError: [Errno 2] No such file or directory: '/home/hp/Downloads/20181024_d1_0830_0900(2).csv'
[2023-12-25T07:46:01.769+0000] {taskinstance.py:1138} INFO - Marking task as UP_FOR_RETRY. dag_id=traffic_flow, task_id=Extract, execution_date=20230215T000000, start_date=20231225T074601, end_date=20231225T074601
[2023-12-25T07:46:02.023+0000] {standard_task_runner.py:107} ERROR - Failed to execute job 84 for task Extract ([Errno 2] No such file or directory: '/home/hp/Downloads/20181024_d1_0830_0900(2).csv'; 603)
[2023-12-25T07:46:02.082+0000] {local_task_job_runner.py:234} INFO - Task exited with return code 1
[2023-12-25T07:46:02.242+0000] {taskinstance.py:3281} INFO - 0 downstream tasks scheduled from follow-on schedule check
