[2023-12-25T02:23:23.281+0000] {taskinstance.py:1957} INFO - Dependencies all met for dep_context=non-requeueable deps ti=<TaskInstance: traffic_flow.Extract scheduled__2023-01-06T00:00:00+00:00 [queued]>
[2023-12-25T02:23:23.296+0000] {taskinstance.py:1957} INFO - Dependencies all met for dep_context=requeueable deps ti=<TaskInstance: traffic_flow.Extract scheduled__2023-01-06T00:00:00+00:00 [queued]>
[2023-12-25T02:23:23.297+0000] {taskinstance.py:2171} INFO - Starting attempt 2 of 2
[2023-12-25T02:23:23.482+0000] {taskinstance.py:2192} INFO - Executing <Task(PythonOperator): Extract> on 2023-01-06 00:00:00+00:00
[2023-12-25T02:23:23.515+0000] {standard_task_runner.py:60} INFO - Started process 10600 to run task
[2023-12-25T02:23:23.546+0000] {standard_task_runner.py:87} INFO - Running: ['***', 'tasks', 'run', 'traffic_flow', 'Extract', 'scheduled__2023-01-06T00:00:00+00:00', '--job-id', '11', '--raw', '--subdir', 'DAGS_FOLDER/main.py', '--cfg-path', '/tmp/tmpg5_qct13']
[2023-12-25T02:23:23.561+0000] {standard_task_runner.py:88} INFO - Job 11: Subtask Extract
[2023-12-25T02:23:23.720+0000] {logging_mixin.py:188} WARNING - /home/***/.local/lib/python3.8/site-packages/***/settings.py:195 DeprecationWarning: The sql_alchemy_conn option in [core] has been moved to the sql_alchemy_conn option in [database] - the old setting has been used, but please update your config.
[2023-12-25T02:23:24.575+0000] {task_command.py:423} INFO - Running <TaskInstance: traffic_flow.Extract scheduled__2023-01-06T00:00:00+00:00 [running]> on host 9f4b92a38ae3
[2023-12-25T02:23:43.475+0000] {taskinstance.py:2481} INFO - Exporting env vars: AIRFLOW_CTX_DAG_OWNER='***' AIRFLOW_CTX_DAG_ID='traffic_flow' AIRFLOW_CTX_TASK_ID='Extract' AIRFLOW_CTX_EXECUTION_DATE='2023-01-06T00:00:00+00:00' AIRFLOW_CTX_TRY_NUMBER='2' AIRFLOW_CTX_DAG_RUN_ID='scheduled__2023-01-06T00:00:00+00:00'
[2023-12-25T02:23:45.333+0000] {taskinstance.py:2699} ERROR - Task failed with exception
Traceback (most recent call last):
  File "/home/airflow/.local/lib/python3.8/site-packages/airflow/models/taskinstance.py", line 433, in _execute_task
    result = execute_callable(context=context, **execute_callable_kwargs)
  File "/home/airflow/.local/lib/python3.8/site-packages/airflow/operators/python.py", line 199, in execute
    return_value = self.execute_callable()
  File "/home/airflow/.local/lib/python3.8/site-packages/airflow/operators/python.py", line 216, in execute_callable
    return self.python_callable(*self.op_args, **self.op_kwargs)
  File "/opt/airflow/dags/main.py", line 31, in task_a_function
    csv_reader.read_data()
  File "/opt/airflow/dags/src/extract_data_source.py", line 10, in read_data
    with open(self.csv_path, 'r') as file:
FileNotFoundError: [Errno 2] No such file or directory: '/home/hp/Downloads/20181024_d1_0830_0900(2).csv'
[2023-12-25T02:23:46.327+0000] {taskinstance.py:1138} INFO - Marking task as FAILED. dag_id=traffic_flow, task_id=Extract, execution_date=20230106T000000, start_date=20231225T022323, end_date=20231225T022346
[2023-12-25T02:24:06.075+0000] {standard_task_runner.py:107} ERROR - Failed to execute job 11 for task Extract ([Errno 2] No such file or directory: '/home/hp/Downloads/20181024_d1_0830_0900(2).csv'; 10600)
[2023-12-25T02:24:06.695+0000] {local_task_job_runner.py:234} INFO - Task exited with return code 1
[2023-12-25T02:24:06.756+0000] {taskinstance.py:3281} INFO - 0 downstream tasks scheduled from follow-on schedule check
[2023-12-25T07:35:11.174+0000] {logging_mixin.py:188} INFO - Changing /opt/***/logs/dag_id=traffic_flow/run_id=scheduled__2023-01-06T00:00:00+00:00/task_id=Extract permission to 509
[2023-12-25T07:35:11.181+0000] {logging_mixin.py:188} INFO - Failed to change /opt/***/logs/dag_id=traffic_flow/run_id=scheduled__2023-01-06T00:00:00+00:00/task_id=Extract permission to 509: [Errno 1] Operation not permitted: '/opt/***/logs/dag_id=traffic_flow/run_id=scheduled__2023-01-06T00:00:00+00:00/task_id=Extract'
[2023-12-25T07:35:11.794+0000] {logging_mixin.py:188} INFO - Changing /opt/***/logs/dag_id=traffic_flow/run_id=scheduled__2023-01-06T00:00:00+00:00/task_id=Extract permission to 509
[2023-12-25T07:35:11.795+0000] {logging_mixin.py:188} INFO - Failed to change /opt/***/logs/dag_id=traffic_flow/run_id=scheduled__2023-01-06T00:00:00+00:00/task_id=Extract permission to 509: [Errno 1] Operation not permitted: '/opt/***/logs/dag_id=traffic_flow/run_id=scheduled__2023-01-06T00:00:00+00:00/task_id=Extract'
[2023-12-25T07:35:13.940+0000] {taskinstance.py:1957} INFO - Dependencies all met for dep_context=non-requeueable deps ti=<TaskInstance: traffic_flow.Extract scheduled__2023-01-06T00:00:00+00:00 [queued]>
[2023-12-25T07:35:14.049+0000] {taskinstance.py:1957} INFO - Dependencies all met for dep_context=requeueable deps ti=<TaskInstance: traffic_flow.Extract scheduled__2023-01-06T00:00:00+00:00 [queued]>
[2023-12-25T07:35:14.050+0000] {taskinstance.py:2171} INFO - Starting attempt 2 of 2
[2023-12-25T07:35:14.395+0000] {taskinstance.py:2192} INFO - Executing <Task(PythonOperator): Extract> on 2023-01-06 00:00:00+00:00
[2023-12-25T07:35:14.417+0000] {standard_task_runner.py:60} INFO - Started process 357 to run task
[2023-12-25T07:35:14.458+0000] {standard_task_runner.py:87} INFO - Running: ['***', 'tasks', 'run', 'traffic_flow', 'Extract', 'scheduled__2023-01-06T00:00:00+00:00', '--job-id', '30', '--raw', '--subdir', 'DAGS_FOLDER/main.py', '--cfg-path', '/tmp/tmppgzs844v']
[2023-12-25T07:35:14.481+0000] {standard_task_runner.py:88} INFO - Job 30: Subtask Extract
[2023-12-25T07:35:17.967+0000] {logging_mixin.py:188} WARNING - /home/***/.local/lib/python3.8/site-packages/***/settings.py:195 DeprecationWarning: The sql_alchemy_conn option in [core] has been moved to the sql_alchemy_conn option in [database] - the old setting has been used, but please update your config.
[2023-12-25T07:35:18.889+0000] {logging_mixin.py:188} INFO - Changing /opt/***/logs/dag_id=traffic_flow/run_id=scheduled__2023-01-06T00:00:00+00:00/task_id=Extract permission to 509
[2023-12-25T07:35:18.936+0000] {logging_mixin.py:188} INFO - Failed to change /opt/***/logs/dag_id=traffic_flow/run_id=scheduled__2023-01-06T00:00:00+00:00/task_id=Extract permission to 509: [Errno 1] Operation not permitted: '/opt/***/logs/dag_id=traffic_flow/run_id=scheduled__2023-01-06T00:00:00+00:00/task_id=Extract'
[2023-12-25T07:35:19.128+0000] {task_command.py:423} INFO - Running <TaskInstance: traffic_flow.Extract scheduled__2023-01-06T00:00:00+00:00 [running]> on host b33131cfaa7f
[2023-12-25T07:35:27.468+0000] {taskinstance.py:2481} INFO - Exporting env vars: AIRFLOW_CTX_DAG_OWNER='***' AIRFLOW_CTX_DAG_ID='traffic_flow' AIRFLOW_CTX_TASK_ID='Extract' AIRFLOW_CTX_EXECUTION_DATE='2023-01-06T00:00:00+00:00' AIRFLOW_CTX_TRY_NUMBER='2' AIRFLOW_CTX_DAG_RUN_ID='scheduled__2023-01-06T00:00:00+00:00'
[2023-12-25T07:35:27.606+0000] {taskinstance.py:2699} ERROR - Task failed with exception
Traceback (most recent call last):
  File "/home/airflow/.local/lib/python3.8/site-packages/airflow/models/taskinstance.py", line 433, in _execute_task
    result = execute_callable(context=context, **execute_callable_kwargs)
  File "/home/airflow/.local/lib/python3.8/site-packages/airflow/operators/python.py", line 199, in execute
    return_value = self.execute_callable()
  File "/home/airflow/.local/lib/python3.8/site-packages/airflow/operators/python.py", line 216, in execute_callable
    return self.python_callable(*self.op_args, **self.op_kwargs)
  File "/opt/airflow/dags/main.py", line 31, in task_a_function
    csv_reader.read_data()
  File "/opt/airflow/dags/src/extract_data_source.py", line 10, in read_data
    with open(self.csv_path, 'r') as file:
FileNotFoundError: [Errno 2] No such file or directory: '/home/hp/Downloads/20181024_d1_0830_0900(2).csv'
[2023-12-25T07:35:28.390+0000] {taskinstance.py:1138} INFO - Marking task as FAILED. dag_id=traffic_flow, task_id=Extract, execution_date=20230106T000000, start_date=20231225T073513, end_date=20231225T073527
[2023-12-25T07:38:12.207+0000] {standard_task_runner.py:107} ERROR - Failed to execute job 30 for task Extract ([Errno 2] No such file or directory: '/home/hp/Downloads/20181024_d1_0830_0900(2).csv'; 357)
[2023-12-25T07:38:12.680+0000] {local_task_job_runner.py:234} INFO - Task exited with return code 1
[2023-12-25T07:38:14.315+0000] {taskinstance.py:3281} INFO - 0 downstream tasks scheduled from follow-on schedule check
