[2023-12-25T02:23:23.351+0000] {taskinstance.py:1957} INFO - Dependencies all met for dep_context=non-requeueable deps ti=<TaskInstance: traffic_flow.Extract scheduled__2023-01-03T00:00:00+00:00 [queued]>
[2023-12-25T02:23:23.385+0000] {taskinstance.py:1957} INFO - Dependencies all met for dep_context=requeueable deps ti=<TaskInstance: traffic_flow.Extract scheduled__2023-01-03T00:00:00+00:00 [queued]>
[2023-12-25T02:23:23.386+0000] {taskinstance.py:2171} INFO - Starting attempt 2 of 2
[2023-12-25T02:23:23.621+0000] {taskinstance.py:2192} INFO - Executing <Task(PythonOperator): Extract> on 2023-01-03 00:00:00+00:00
[2023-12-25T02:23:23.634+0000] {standard_task_runner.py:60} INFO - Started process 10605 to run task
[2023-12-25T02:23:23.736+0000] {standard_task_runner.py:87} INFO - Running: ['***', 'tasks', 'run', 'traffic_flow', 'Extract', 'scheduled__2023-01-03T00:00:00+00:00', '--job-id', '12', '--raw', '--subdir', 'DAGS_FOLDER/main.py', '--cfg-path', '/tmp/tmp8f6c720p']
[2023-12-25T02:23:23.742+0000] {standard_task_runner.py:88} INFO - Job 12: Subtask Extract
[2023-12-25T02:23:24.193+0000] {cli_action_loggers.py:135} WARNING - Failed to log action (psycopg2.OperationalError) connection to server at "postgres" (172.19.0.2), port 5432 failed: could not fork new process for connection: Cannot allocate memory

(Background on this error at: https://sqlalche.me/e/14/e3q8)
[2023-12-25T02:23:24.404+0000] {logging_mixin.py:188} WARNING - /home/***/.local/lib/python3.8/site-packages/***/settings.py:195 DeprecationWarning: The sql_alchemy_conn option in [core] has been moved to the sql_alchemy_conn option in [database] - the old setting has been used, but please update your config.
[2023-12-25T02:23:26.878+0000] {task_command.py:423} INFO - Running <TaskInstance: traffic_flow.Extract scheduled__2023-01-03T00:00:00+00:00 [running]> on host 9f4b92a38ae3
[2023-12-25T02:23:43.475+0000] {taskinstance.py:2481} INFO - Exporting env vars: AIRFLOW_CTX_DAG_OWNER='***' AIRFLOW_CTX_DAG_ID='traffic_flow' AIRFLOW_CTX_TASK_ID='Extract' AIRFLOW_CTX_EXECUTION_DATE='2023-01-03T00:00:00+00:00' AIRFLOW_CTX_TRY_NUMBER='2' AIRFLOW_CTX_DAG_RUN_ID='scheduled__2023-01-03T00:00:00+00:00'
[2023-12-25T02:23:45.129+0000] {taskinstance.py:2699} ERROR - Task failed with exception
Traceback (most recent call last):
  File "/home/airflow/.local/lib/python3.8/site-packages/airflow/models/taskinstance.py", line 433, in _execute_task
    result = execute_callable(context=context, **execute_callable_kwargs)
  File "/home/airflow/.local/lib/python3.8/site-packages/airflow/operators/python.py", line 199, in execute
    return_value = self.execute_callable()
  File "/home/airflow/.local/lib/python3.8/site-packages/airflow/operators/python.py", line 216, in execute_callable
    return self.python_callable(*self.op_args, **self.op_kwargs)
  File "/opt/airflow/dags/main.py", line 31, in task_a_function
    csv_reader.read_data()
  File "/opt/airflow/dags/src/extract_data_source.py", line 10, in read_data
    with open(self.csv_path, 'r') as file:
FileNotFoundError: [Errno 2] No such file or directory: '/home/hp/Downloads/20181024_d1_0830_0900(2).csv'
[2023-12-25T02:24:05.656+0000] {taskinstance.py:1138} INFO - Marking task as FAILED. dag_id=traffic_flow, task_id=Extract, execution_date=20230103T000000, start_date=20231225T022323, end_date=20231225T022405
[2023-12-25T02:24:06.062+0000] {standard_task_runner.py:107} ERROR - Failed to execute job 12 for task Extract ([Errno 2] No such file or directory: '/home/hp/Downloads/20181024_d1_0830_0900(2).csv'; 10605)
[2023-12-25T02:24:06.699+0000] {local_task_job_runner.py:234} INFO - Task exited with return code 1
[2023-12-25T02:24:06.781+0000] {taskinstance.py:3281} INFO - 0 downstream tasks scheduled from follow-on schedule check
[2023-12-25T07:35:11.160+0000] {logging_mixin.py:188} INFO - Changing /opt/***/logs/dag_id=traffic_flow/run_id=scheduled__2023-01-03T00:00:00+00:00/task_id=Extract permission to 509
[2023-12-25T07:35:11.160+0000] {logging_mixin.py:188} INFO - Failed to change /opt/***/logs/dag_id=traffic_flow/run_id=scheduled__2023-01-03T00:00:00+00:00/task_id=Extract permission to 509: [Errno 1] Operation not permitted: '/opt/***/logs/dag_id=traffic_flow/run_id=scheduled__2023-01-03T00:00:00+00:00/task_id=Extract'
[2023-12-25T07:35:11.798+0000] {logging_mixin.py:188} INFO - Changing /opt/***/logs/dag_id=traffic_flow/run_id=scheduled__2023-01-03T00:00:00+00:00/task_id=Extract permission to 509
[2023-12-25T07:35:11.799+0000] {logging_mixin.py:188} INFO - Failed to change /opt/***/logs/dag_id=traffic_flow/run_id=scheduled__2023-01-03T00:00:00+00:00/task_id=Extract permission to 509: [Errno 1] Operation not permitted: '/opt/***/logs/dag_id=traffic_flow/run_id=scheduled__2023-01-03T00:00:00+00:00/task_id=Extract'
[2023-12-25T07:35:13.947+0000] {taskinstance.py:1957} INFO - Dependencies all met for dep_context=non-requeueable deps ti=<TaskInstance: traffic_flow.Extract scheduled__2023-01-03T00:00:00+00:00 [queued]>
[2023-12-25T07:35:14.063+0000] {taskinstance.py:1957} INFO - Dependencies all met for dep_context=requeueable deps ti=<TaskInstance: traffic_flow.Extract scheduled__2023-01-03T00:00:00+00:00 [queued]>
[2023-12-25T07:35:14.064+0000] {taskinstance.py:2171} INFO - Starting attempt 2 of 2
[2023-12-25T07:35:14.385+0000] {taskinstance.py:2192} INFO - Executing <Task(PythonOperator): Extract> on 2023-01-03 00:00:00+00:00
[2023-12-25T07:35:14.424+0000] {standard_task_runner.py:60} INFO - Started process 359 to run task
[2023-12-25T07:35:14.443+0000] {standard_task_runner.py:87} INFO - Running: ['***', 'tasks', 'run', 'traffic_flow', 'Extract', 'scheduled__2023-01-03T00:00:00+00:00', '--job-id', '29', '--raw', '--subdir', 'DAGS_FOLDER/main.py', '--cfg-path', '/tmp/tmp7b074ogx']
[2023-12-25T07:35:14.860+0000] {standard_task_runner.py:88} INFO - Job 29: Subtask Extract
[2023-12-25T07:35:16.926+0000] {logging_mixin.py:188} WARNING - /home/***/.local/lib/python3.8/site-packages/***/settings.py:195 DeprecationWarning: The sql_alchemy_conn option in [core] has been moved to the sql_alchemy_conn option in [database] - the old setting has been used, but please update your config.
[2023-12-25T07:35:18.126+0000] {logging_mixin.py:188} INFO - Changing /opt/***/logs/dag_id=traffic_flow/run_id=scheduled__2023-01-03T00:00:00+00:00/task_id=Extract permission to 509
[2023-12-25T07:35:18.126+0000] {logging_mixin.py:188} INFO - Failed to change /opt/***/logs/dag_id=traffic_flow/run_id=scheduled__2023-01-03T00:00:00+00:00/task_id=Extract permission to 509: [Errno 1] Operation not permitted: '/opt/***/logs/dag_id=traffic_flow/run_id=scheduled__2023-01-03T00:00:00+00:00/task_id=Extract'
[2023-12-25T07:35:18.132+0000] {task_command.py:423} INFO - Running <TaskInstance: traffic_flow.Extract scheduled__2023-01-03T00:00:00+00:00 [running]> on host b33131cfaa7f
[2023-12-25T07:35:27.472+0000] {taskinstance.py:2481} INFO - Exporting env vars: AIRFLOW_CTX_DAG_OWNER='***' AIRFLOW_CTX_DAG_ID='traffic_flow' AIRFLOW_CTX_TASK_ID='Extract' AIRFLOW_CTX_EXECUTION_DATE='2023-01-03T00:00:00+00:00' AIRFLOW_CTX_TRY_NUMBER='2' AIRFLOW_CTX_DAG_RUN_ID='scheduled__2023-01-03T00:00:00+00:00'
[2023-12-25T07:35:27.498+0000] {taskinstance.py:2699} ERROR - Task failed with exception
Traceback (most recent call last):
  File "/home/airflow/.local/lib/python3.8/site-packages/airflow/models/taskinstance.py", line 433, in _execute_task
    result = execute_callable(context=context, **execute_callable_kwargs)
  File "/home/airflow/.local/lib/python3.8/site-packages/airflow/operators/python.py", line 199, in execute
    return_value = self.execute_callable()
  File "/home/airflow/.local/lib/python3.8/site-packages/airflow/operators/python.py", line 216, in execute_callable
    return self.python_callable(*self.op_args, **self.op_kwargs)
  File "/opt/airflow/dags/main.py", line 31, in task_a_function
    csv_reader.read_data()
  File "/opt/airflow/dags/src/extract_data_source.py", line 10, in read_data
    with open(self.csv_path, 'r') as file:
FileNotFoundError: [Errno 2] No such file or directory: '/home/hp/Downloads/20181024_d1_0830_0900(2).csv'
[2023-12-25T07:35:28.392+0000] {taskinstance.py:1138} INFO - Marking task as FAILED. dag_id=traffic_flow, task_id=Extract, execution_date=20230103T000000, start_date=20231225T073513, end_date=20231225T073528
[2023-12-25T07:38:12.360+0000] {standard_task_runner.py:107} ERROR - Failed to execute job 29 for task Extract ([Errno 2] No such file or directory: '/home/hp/Downloads/20181024_d1_0830_0900(2).csv'; 359)
[2023-12-25T07:38:12.443+0000] {local_task_job_runner.py:234} INFO - Task exited with return code 1
[2023-12-25T07:38:13.239+0000] {taskinstance.py:3281} INFO - 0 downstream tasks scheduled from follow-on schedule check
