[2023-12-25T02:24:40.169+0000] {taskinstance.py:1957} INFO - Dependencies all met for dep_context=non-requeueable deps ti=<TaskInstance: traffic_flow.Extract scheduled__2023-01-24T00:00:00+00:00 [queued]>
[2023-12-25T02:24:40.187+0000] {taskinstance.py:1957} INFO - Dependencies all met for dep_context=requeueable deps ti=<TaskInstance: traffic_flow.Extract scheduled__2023-01-24T00:00:00+00:00 [queued]>
[2023-12-25T02:24:40.188+0000] {taskinstance.py:2171} INFO - Starting attempt 1 of 2
[2023-12-25T02:24:40.340+0000] {taskinstance.py:2192} INFO - Executing <Task(PythonOperator): Extract> on 2023-01-24 00:00:00+00:00
[2023-12-25T02:24:40.350+0000] {standard_task_runner.py:60} INFO - Started process 10787 to run task
[2023-12-25T02:24:40.360+0000] {standard_task_runner.py:87} INFO - Running: ['***', 'tasks', 'run', 'traffic_flow', 'Extract', 'scheduled__2023-01-24T00:00:00+00:00', '--job-id', '30', '--raw', '--subdir', 'DAGS_FOLDER/main.py', '--cfg-path', '/tmp/tmpd3soon29']
[2023-12-25T02:24:40.366+0000] {standard_task_runner.py:88} INFO - Job 30: Subtask Extract
[2023-12-25T02:24:40.514+0000] {logging_mixin.py:188} WARNING - /home/***/.local/lib/python3.8/site-packages/***/settings.py:195 DeprecationWarning: The sql_alchemy_conn option in [core] has been moved to the sql_alchemy_conn option in [database] - the old setting has been used, but please update your config.
[2023-12-25T02:24:40.626+0000] {task_command.py:423} INFO - Running <TaskInstance: traffic_flow.Extract scheduled__2023-01-24T00:00:00+00:00 [running]> on host 9f4b92a38ae3
[2023-12-25T02:24:40.975+0000] {taskinstance.py:2481} INFO - Exporting env vars: AIRFLOW_CTX_DAG_OWNER='***' AIRFLOW_CTX_DAG_ID='traffic_flow' AIRFLOW_CTX_TASK_ID='Extract' AIRFLOW_CTX_EXECUTION_DATE='2023-01-24T00:00:00+00:00' AIRFLOW_CTX_TRY_NUMBER='1' AIRFLOW_CTX_DAG_RUN_ID='scheduled__2023-01-24T00:00:00+00:00'
[2023-12-25T02:24:40.978+0000] {taskinstance.py:2699} ERROR - Task failed with exception
Traceback (most recent call last):
  File "/home/airflow/.local/lib/python3.8/site-packages/airflow/models/taskinstance.py", line 433, in _execute_task
    result = execute_callable(context=context, **execute_callable_kwargs)
  File "/home/airflow/.local/lib/python3.8/site-packages/airflow/operators/python.py", line 199, in execute
    return_value = self.execute_callable()
  File "/home/airflow/.local/lib/python3.8/site-packages/airflow/operators/python.py", line 216, in execute_callable
    return self.python_callable(*self.op_args, **self.op_kwargs)
  File "/opt/airflow/dags/main.py", line 31, in task_a_function
    csv_reader.read_data()
  File "/opt/airflow/dags/src/extract_data_source.py", line 10, in read_data
    with open(self.csv_path, 'r') as file:
FileNotFoundError: [Errno 2] No such file or directory: '/home/hp/Downloads/20181024_d1_0830_0900(2).csv'
[2023-12-25T02:24:41.021+0000] {taskinstance.py:1138} INFO - Marking task as UP_FOR_RETRY. dag_id=traffic_flow, task_id=Extract, execution_date=20230124T000000, start_date=20231225T022440, end_date=20231225T022441
[2023-12-25T02:24:41.496+0000] {standard_task_runner.py:107} ERROR - Failed to execute job 30 for task Extract ([Errno 2] No such file or directory: '/home/hp/Downloads/20181024_d1_0830_0900(2).csv'; 10787)
[2023-12-25T02:24:41.539+0000] {local_task_job_runner.py:234} INFO - Task exited with return code 1
[2023-12-25T02:24:41.616+0000] {taskinstance.py:3281} INFO - 0 downstream tasks scheduled from follow-on schedule check
[2023-12-25T07:40:04.068+0000] {logging_mixin.py:188} INFO - Changing /opt/***/logs/dag_id=traffic_flow/run_id=scheduled__2023-01-24T00:00:00+00:00/task_id=Extract permission to 509
[2023-12-25T07:40:04.069+0000] {logging_mixin.py:188} INFO - Failed to change /opt/***/logs/dag_id=traffic_flow/run_id=scheduled__2023-01-24T00:00:00+00:00/task_id=Extract permission to 509: [Errno 1] Operation not permitted: '/opt/***/logs/dag_id=traffic_flow/run_id=scheduled__2023-01-24T00:00:00+00:00/task_id=Extract'
[2023-12-25T07:40:04.565+0000] {logging_mixin.py:188} INFO - Changing /opt/***/logs/dag_id=traffic_flow/run_id=scheduled__2023-01-24T00:00:00+00:00/task_id=Extract permission to 509
[2023-12-25T07:40:04.565+0000] {logging_mixin.py:188} INFO - Failed to change /opt/***/logs/dag_id=traffic_flow/run_id=scheduled__2023-01-24T00:00:00+00:00/task_id=Extract permission to 509: [Errno 1] Operation not permitted: '/opt/***/logs/dag_id=traffic_flow/run_id=scheduled__2023-01-24T00:00:00+00:00/task_id=Extract'
[2023-12-25T07:40:05.650+0000] {taskinstance.py:1957} INFO - Dependencies all met for dep_context=non-requeueable deps ti=<TaskInstance: traffic_flow.Extract scheduled__2023-01-24T00:00:00+00:00 [queued]>
[2023-12-25T07:40:05.731+0000] {taskinstance.py:1957} INFO - Dependencies all met for dep_context=requeueable deps ti=<TaskInstance: traffic_flow.Extract scheduled__2023-01-24T00:00:00+00:00 [queued]>
[2023-12-25T07:40:05.732+0000] {taskinstance.py:2171} INFO - Starting attempt 1 of 2
[2023-12-25T07:40:05.901+0000] {taskinstance.py:2192} INFO - Executing <Task(PythonOperator): Extract> on 2023-01-24 00:00:00+00:00
[2023-12-25T07:40:05.914+0000] {standard_task_runner.py:60} INFO - Started process 436 to run task
[2023-12-25T07:40:05.922+0000] {standard_task_runner.py:87} INFO - Running: ['***', 'tasks', 'run', 'traffic_flow', 'Extract', 'scheduled__2023-01-24T00:00:00+00:00', '--job-id', '50', '--raw', '--subdir', 'DAGS_FOLDER/main.py', '--cfg-path', '/tmp/tmpn6iutla8']
[2023-12-25T07:40:05.926+0000] {standard_task_runner.py:88} INFO - Job 50: Subtask Extract
[2023-12-25T07:40:06.200+0000] {logging_mixin.py:188} WARNING - /home/***/.local/lib/python3.8/site-packages/***/settings.py:195 DeprecationWarning: The sql_alchemy_conn option in [core] has been moved to the sql_alchemy_conn option in [database] - the old setting has been used, but please update your config.
[2023-12-25T07:40:06.496+0000] {logging_mixin.py:188} INFO - Changing /opt/***/logs/dag_id=traffic_flow/run_id=scheduled__2023-01-24T00:00:00+00:00/task_id=Extract permission to 509
[2023-12-25T07:40:06.496+0000] {logging_mixin.py:188} INFO - Failed to change /opt/***/logs/dag_id=traffic_flow/run_id=scheduled__2023-01-24T00:00:00+00:00/task_id=Extract permission to 509: [Errno 1] Operation not permitted: '/opt/***/logs/dag_id=traffic_flow/run_id=scheduled__2023-01-24T00:00:00+00:00/task_id=Extract'
[2023-12-25T07:40:06.497+0000] {task_command.py:423} INFO - Running <TaskInstance: traffic_flow.Extract scheduled__2023-01-24T00:00:00+00:00 [running]> on host b33131cfaa7f
[2023-12-25T07:40:07.542+0000] {taskinstance.py:2481} INFO - Exporting env vars: AIRFLOW_CTX_DAG_OWNER='***' AIRFLOW_CTX_DAG_ID='traffic_flow' AIRFLOW_CTX_TASK_ID='Extract' AIRFLOW_CTX_EXECUTION_DATE='2023-01-24T00:00:00+00:00' AIRFLOW_CTX_TRY_NUMBER='1' AIRFLOW_CTX_DAG_RUN_ID='scheduled__2023-01-24T00:00:00+00:00'
[2023-12-25T07:40:07.549+0000] {taskinstance.py:2699} ERROR - Task failed with exception
Traceback (most recent call last):
  File "/home/airflow/.local/lib/python3.8/site-packages/airflow/models/taskinstance.py", line 433, in _execute_task
    result = execute_callable(context=context, **execute_callable_kwargs)
  File "/home/airflow/.local/lib/python3.8/site-packages/airflow/operators/python.py", line 199, in execute
    return_value = self.execute_callable()
  File "/home/airflow/.local/lib/python3.8/site-packages/airflow/operators/python.py", line 216, in execute_callable
    return self.python_callable(*self.op_args, **self.op_kwargs)
  File "/opt/airflow/dags/main.py", line 31, in task_a_function
    csv_reader.read_data()
  File "/opt/airflow/dags/src/extract_data_source.py", line 10, in read_data
    with open(self.csv_path, 'r') as file:
FileNotFoundError: [Errno 2] No such file or directory: '/home/hp/Downloads/20181024_d1_0830_0900(2).csv'
[2023-12-25T07:40:07.649+0000] {taskinstance.py:1138} INFO - Marking task as UP_FOR_RETRY. dag_id=traffic_flow, task_id=Extract, execution_date=20230124T000000, start_date=20231225T074005, end_date=20231225T074007
[2023-12-25T07:40:10.876+0000] {standard_task_runner.py:107} ERROR - Failed to execute job 50 for task Extract ([Errno 2] No such file or directory: '/home/hp/Downloads/20181024_d1_0830_0900(2).csv'; 436)
[2023-12-25T07:40:10.926+0000] {local_task_job_runner.py:234} INFO - Task exited with return code 1
[2023-12-25T07:40:11.280+0000] {taskinstance.py:3281} INFO - 0 downstream tasks scheduled from follow-on schedule check
