[2023-12-25T02:23:20.968+0000] {taskinstance.py:1957} INFO - Dependencies all met for dep_context=non-requeueable deps ti=<TaskInstance: traffic_flow.Extract scheduled__2023-01-01T00:00:00+00:00 [queued]>
[2023-12-25T02:23:21.005+0000] {taskinstance.py:1957} INFO - Dependencies all met for dep_context=requeueable deps ti=<TaskInstance: traffic_flow.Extract scheduled__2023-01-01T00:00:00+00:00 [queued]>
[2023-12-25T02:23:21.006+0000] {taskinstance.py:2171} INFO - Starting attempt 2 of 2
[2023-12-25T02:23:21.493+0000] {taskinstance.py:2192} INFO - Executing <Task(PythonOperator): Extract> on 2023-01-01 00:00:00+00:00
[2023-12-25T02:23:21.503+0000] {standard_task_runner.py:60} INFO - Started process 10591 to run task
[2023-12-25T02:23:21.559+0000] {standard_task_runner.py:87} INFO - Running: ['***', 'tasks', 'run', 'traffic_flow', 'Extract', 'scheduled__2023-01-01T00:00:00+00:00', '--job-id', '6', '--raw', '--subdir', 'DAGS_FOLDER/main.py', '--cfg-path', '/tmp/tmpown7h0sy']
[2023-12-25T02:23:21.579+0000] {standard_task_runner.py:88} INFO - Job 6: Subtask Extract
[2023-12-25T02:23:22.092+0000] {logging_mixin.py:188} WARNING - /home/***/.local/lib/python3.8/site-packages/***/settings.py:195 DeprecationWarning: The sql_alchemy_conn option in [core] has been moved to the sql_alchemy_conn option in [database] - the old setting has been used, but please update your config.
[2023-12-25T02:23:22.189+0000] {task_command.py:423} INFO - Running <TaskInstance: traffic_flow.Extract scheduled__2023-01-01T00:00:00+00:00 [running]> on host 9f4b92a38ae3
[2023-12-25T02:23:26.850+0000] {taskinstance.py:2481} INFO - Exporting env vars: AIRFLOW_CTX_DAG_OWNER='***' AIRFLOW_CTX_DAG_ID='traffic_flow' AIRFLOW_CTX_TASK_ID='Extract' AIRFLOW_CTX_EXECUTION_DATE='2023-01-01T00:00:00+00:00' AIRFLOW_CTX_TRY_NUMBER='2' AIRFLOW_CTX_DAG_RUN_ID='scheduled__2023-01-01T00:00:00+00:00'
[2023-12-25T02:23:27.755+0000] {taskinstance.py:2699} ERROR - Task failed with exception
Traceback (most recent call last):
  File "/home/airflow/.local/lib/python3.8/site-packages/airflow/models/taskinstance.py", line 433, in _execute_task
    result = execute_callable(context=context, **execute_callable_kwargs)
  File "/home/airflow/.local/lib/python3.8/site-packages/airflow/operators/python.py", line 199, in execute
    return_value = self.execute_callable()
  File "/home/airflow/.local/lib/python3.8/site-packages/airflow/operators/python.py", line 216, in execute_callable
    return self.python_callable(*self.op_args, **self.op_kwargs)
  File "/opt/airflow/dags/main.py", line 31, in task_a_function
    csv_reader.read_data()
  File "/opt/airflow/dags/src/extract_data_source.py", line 10, in read_data
    with open(self.csv_path, 'r') as file:
FileNotFoundError: [Errno 2] No such file or directory: '/home/hp/Downloads/20181024_d1_0830_0900(2).csv'
[2023-12-25T02:23:42.764+0000] {taskinstance.py:1138} INFO - Marking task as FAILED. dag_id=traffic_flow, task_id=Extract, execution_date=20230101T000000, start_date=20231225T022320, end_date=20231225T022342
[2023-12-25T02:24:06.072+0000] {standard_task_runner.py:107} ERROR - Failed to execute job 6 for task Extract ([Errno 2] No such file or directory: '/home/hp/Downloads/20181024_d1_0830_0900(2).csv'; 10591)
[2023-12-25T02:24:06.658+0000] {local_task_job_runner.py:234} INFO - Task exited with return code 1
[2023-12-25T02:24:06.754+0000] {taskinstance.py:3281} INFO - 0 downstream tasks scheduled from follow-on schedule check
