[2023-12-25T02:23:23.311+0000] {taskinstance.py:1957} INFO - Dependencies all met for dep_context=non-requeueable deps ti=<TaskInstance: traffic_flow.Extract scheduled__2023-01-04T00:00:00+00:00 [queued]>
[2023-12-25T02:23:23.340+0000] {taskinstance.py:1957} INFO - Dependencies all met for dep_context=requeueable deps ti=<TaskInstance: traffic_flow.Extract scheduled__2023-01-04T00:00:00+00:00 [queued]>
[2023-12-25T02:23:23.340+0000] {taskinstance.py:2171} INFO - Starting attempt 2 of 2
[2023-12-25T02:23:23.489+0000] {taskinstance.py:2192} INFO - Executing <Task(PythonOperator): Extract> on 2023-01-04 00:00:00+00:00
[2023-12-25T02:23:23.520+0000] {standard_task_runner.py:60} INFO - Started process 10601 to run task
[2023-12-25T02:23:23.548+0000] {standard_task_runner.py:87} INFO - Running: ['***', 'tasks', 'run', 'traffic_flow', 'Extract', 'scheduled__2023-01-04T00:00:00+00:00', '--job-id', '9', '--raw', '--subdir', 'DAGS_FOLDER/main.py', '--cfg-path', '/tmp/tmprsjxwkp_']
[2023-12-25T02:23:23.564+0000] {standard_task_runner.py:88} INFO - Job 9: Subtask Extract
[2023-12-25T02:23:23.716+0000] {logging_mixin.py:188} WARNING - /home/***/.local/lib/python3.8/site-packages/***/settings.py:195 DeprecationWarning: The sql_alchemy_conn option in [core] has been moved to the sql_alchemy_conn option in [database] - the old setting has been used, but please update your config.
[2023-12-25T02:23:24.191+0000] {standard_task_runner.py:107} ERROR - Failed to execute job 9 for task Extract ((psycopg2.OperationalError) connection to server at "postgres" (172.19.0.2), port 5432 failed: could not fork new process for connection: Cannot allocate memory

(Background on this error at: https://sqlalche.me/e/14/e3q8); 10601)
[2023-12-25T02:23:24.237+0000] {local_task_job_runner.py:234} INFO - Task exited with return code 1
[2023-12-25T02:23:27.624+0000] {taskinstance.py:3281} INFO - 0 downstream tasks scheduled from follow-on schedule check
[2023-12-25T07:35:11.165+0000] {logging_mixin.py:188} INFO - Changing /opt/***/logs/dag_id=traffic_flow/run_id=scheduled__2023-01-04T00:00:00+00:00/task_id=Extract permission to 509
[2023-12-25T07:35:11.168+0000] {logging_mixin.py:188} INFO - Failed to change /opt/***/logs/dag_id=traffic_flow/run_id=scheduled__2023-01-04T00:00:00+00:00/task_id=Extract permission to 509: [Errno 1] Operation not permitted: '/opt/***/logs/dag_id=traffic_flow/run_id=scheduled__2023-01-04T00:00:00+00:00/task_id=Extract'
[2023-12-25T07:35:11.809+0000] {logging_mixin.py:188} INFO - Changing /opt/***/logs/dag_id=traffic_flow/run_id=scheduled__2023-01-04T00:00:00+00:00/task_id=Extract permission to 509
[2023-12-25T07:35:11.810+0000] {logging_mixin.py:188} INFO - Failed to change /opt/***/logs/dag_id=traffic_flow/run_id=scheduled__2023-01-04T00:00:00+00:00/task_id=Extract permission to 509: [Errno 1] Operation not permitted: '/opt/***/logs/dag_id=traffic_flow/run_id=scheduled__2023-01-04T00:00:00+00:00/task_id=Extract'
[2023-12-25T07:35:13.943+0000] {taskinstance.py:1957} INFO - Dependencies all met for dep_context=non-requeueable deps ti=<TaskInstance: traffic_flow.Extract scheduled__2023-01-04T00:00:00+00:00 [queued]>
[2023-12-25T07:35:14.081+0000] {taskinstance.py:1957} INFO - Dependencies all met for dep_context=requeueable deps ti=<TaskInstance: traffic_flow.Extract scheduled__2023-01-04T00:00:00+00:00 [queued]>
[2023-12-25T07:35:14.082+0000] {taskinstance.py:2171} INFO - Starting attempt 2 of 2
[2023-12-25T07:35:14.399+0000] {taskinstance.py:2192} INFO - Executing <Task(PythonOperator): Extract> on 2023-01-04 00:00:00+00:00
[2023-12-25T07:35:14.451+0000] {standard_task_runner.py:60} INFO - Started process 364 to run task
[2023-12-25T07:35:14.863+0000] {standard_task_runner.py:87} INFO - Running: ['***', 'tasks', 'run', 'traffic_flow', 'Extract', 'scheduled__2023-01-04T00:00:00+00:00', '--job-id', '24', '--raw', '--subdir', 'DAGS_FOLDER/main.py', '--cfg-path', '/tmp/tmpob9i21a2']
[2023-12-25T07:35:14.869+0000] {standard_task_runner.py:88} INFO - Job 24: Subtask Extract
[2023-12-25T07:35:16.916+0000] {logging_mixin.py:188} WARNING - /home/***/.local/lib/python3.8/site-packages/***/settings.py:195 DeprecationWarning: The sql_alchemy_conn option in [core] has been moved to the sql_alchemy_conn option in [database] - the old setting has been used, but please update your config.
[2023-12-25T07:35:18.201+0000] {logging_mixin.py:188} INFO - Changing /opt/***/logs/dag_id=traffic_flow/run_id=scheduled__2023-01-04T00:00:00+00:00/task_id=Extract permission to 509
[2023-12-25T07:35:18.202+0000] {logging_mixin.py:188} INFO - Failed to change /opt/***/logs/dag_id=traffic_flow/run_id=scheduled__2023-01-04T00:00:00+00:00/task_id=Extract permission to 509: [Errno 1] Operation not permitted: '/opt/***/logs/dag_id=traffic_flow/run_id=scheduled__2023-01-04T00:00:00+00:00/task_id=Extract'
[2023-12-25T07:35:18.203+0000] {task_command.py:423} INFO - Running <TaskInstance: traffic_flow.Extract scheduled__2023-01-04T00:00:00+00:00 [running]> on host b33131cfaa7f
[2023-12-25T07:35:27.472+0000] {taskinstance.py:2481} INFO - Exporting env vars: AIRFLOW_CTX_DAG_OWNER='***' AIRFLOW_CTX_DAG_ID='traffic_flow' AIRFLOW_CTX_TASK_ID='Extract' AIRFLOW_CTX_EXECUTION_DATE='2023-01-04T00:00:00+00:00' AIRFLOW_CTX_TRY_NUMBER='2' AIRFLOW_CTX_DAG_RUN_ID='scheduled__2023-01-04T00:00:00+00:00'
[2023-12-25T07:35:27.606+0000] {taskinstance.py:2699} ERROR - Task failed with exception
Traceback (most recent call last):
  File "/home/airflow/.local/lib/python3.8/site-packages/airflow/models/taskinstance.py", line 433, in _execute_task
    result = execute_callable(context=context, **execute_callable_kwargs)
  File "/home/airflow/.local/lib/python3.8/site-packages/airflow/operators/python.py", line 199, in execute
    return_value = self.execute_callable()
  File "/home/airflow/.local/lib/python3.8/site-packages/airflow/operators/python.py", line 216, in execute_callable
    return self.python_callable(*self.op_args, **self.op_kwargs)
  File "/opt/airflow/dags/main.py", line 31, in task_a_function
    csv_reader.read_data()
  File "/opt/airflow/dags/src/extract_data_source.py", line 10, in read_data
    with open(self.csv_path, 'r') as file:
FileNotFoundError: [Errno 2] No such file or directory: '/home/hp/Downloads/20181024_d1_0830_0900(2).csv'
[2023-12-25T07:35:28.412+0000] {taskinstance.py:1138} INFO - Marking task as FAILED. dag_id=traffic_flow, task_id=Extract, execution_date=20230104T000000, start_date=20231225T073513, end_date=20231225T073528
[2023-12-25T07:38:12.337+0000] {standard_task_runner.py:107} ERROR - Failed to execute job 24 for task Extract ([Errno 2] No such file or directory: '/home/hp/Downloads/20181024_d1_0830_0900(2).csv'; 364)
[2023-12-25T07:38:12.626+0000] {local_task_job_runner.py:234} INFO - Task exited with return code 1
[2023-12-25T07:38:14.361+0000] {taskinstance.py:3281} INFO - 0 downstream tasks scheduled from follow-on schedule check
