[2023-12-25T02:46:28.171+0000] {taskinstance.py:1957} INFO - Dependencies all met for dep_context=non-requeueable deps ti=<TaskInstance: traffic_flow.Extract scheduled__2023-02-04T00:00:00+00:00 [queued]>
[2023-12-25T02:46:28.825+0000] {taskinstance.py:1957} INFO - Dependencies all met for dep_context=requeueable deps ti=<TaskInstance: traffic_flow.Extract scheduled__2023-02-04T00:00:00+00:00 [queued]>
[2023-12-25T02:46:28.826+0000] {taskinstance.py:2171} INFO - Starting attempt 2 of 2
[2023-12-25T02:46:29.956+0000] {taskinstance.py:2192} INFO - Executing <Task(PythonOperator): Extract> on 2023-02-04 00:00:00+00:00
[2023-12-25T02:46:29.977+0000] {standard_task_runner.py:60} INFO - Started process 313 to run task
[2023-12-25T02:46:30.050+0000] {standard_task_runner.py:87} INFO - Running: ['***', 'tasks', 'run', 'traffic_flow', 'Extract', 'scheduled__2023-02-04T00:00:00+00:00', '--job-id', '93', '--raw', '--subdir', 'DAGS_FOLDER/main.py', '--cfg-path', '/tmp/tmplcsq5l4u']
[2023-12-25T02:46:30.098+0000] {standard_task_runner.py:88} INFO - Job 93: Subtask Extract
[2023-12-25T02:46:30.800+0000] {logging_mixin.py:188} WARNING - /home/***/.local/lib/python3.8/site-packages/***/settings.py:195 DeprecationWarning: The sql_alchemy_conn option in [core] has been moved to the sql_alchemy_conn option in [database] - the old setting has been used, but please update your config.
[2023-12-25T02:46:33.331+0000] {task_command.py:423} INFO - Running <TaskInstance: traffic_flow.Extract scheduled__2023-02-04T00:00:00+00:00 [running]> on host 9f4b92a38ae3
[2023-12-25T02:46:36.840+0000] {taskinstance.py:2481} INFO - Exporting env vars: AIRFLOW_CTX_DAG_OWNER='***' AIRFLOW_CTX_DAG_ID='traffic_flow' AIRFLOW_CTX_TASK_ID='Extract' AIRFLOW_CTX_EXECUTION_DATE='2023-02-04T00:00:00+00:00' AIRFLOW_CTX_TRY_NUMBER='2' AIRFLOW_CTX_DAG_RUN_ID='scheduled__2023-02-04T00:00:00+00:00'
[2023-12-25T02:46:36.961+0000] {taskinstance.py:2699} ERROR - Task failed with exception
Traceback (most recent call last):
  File "/home/airflow/.local/lib/python3.8/site-packages/airflow/models/taskinstance.py", line 433, in _execute_task
    result = execute_callable(context=context, **execute_callable_kwargs)
  File "/home/airflow/.local/lib/python3.8/site-packages/airflow/operators/python.py", line 199, in execute
    return_value = self.execute_callable()
  File "/home/airflow/.local/lib/python3.8/site-packages/airflow/operators/python.py", line 216, in execute_callable
    return self.python_callable(*self.op_args, **self.op_kwargs)
  File "/opt/airflow/dags/main.py", line 31, in task_a_function
    csv_reader.read_data()
  File "/opt/airflow/dags/src/extract_data_source.py", line 10, in read_data
    with open(self.csv_path, 'r') as file:
FileNotFoundError: [Errno 2] No such file or directory: '/home/hp/Downloads/20181024_d1_0830_0900(2).csv'
[2023-12-25T02:46:37.549+0000] {taskinstance.py:1138} INFO - Marking task as FAILED. dag_id=traffic_flow, task_id=Extract, execution_date=20230204T000000, start_date=20231225T024628, end_date=20231225T024637
[2023-12-25T02:54:08.741+0000] {standard_task_runner.py:107} ERROR - Failed to execute job 93 for task Extract ([Errno 2] No such file or directory: '/home/hp/Downloads/20181024_d1_0830_0900(2).csv'; 313)
[2023-12-25T02:54:09.553+0000] {local_task_job_runner.py:234} INFO - Task exited with return code 1
[2023-12-25T02:54:17.860+0000] {taskinstance.py:3281} INFO - 0 downstream tasks scheduled from follow-on schedule check
[2023-12-25T07:50:57.467+0000] {logging_mixin.py:188} INFO - Changing /opt/***/logs/dag_id=traffic_flow/run_id=scheduled__2023-02-04T00:00:00+00:00/task_id=Extract permission to 509
[2023-12-25T07:50:57.494+0000] {logging_mixin.py:188} INFO - Failed to change /opt/***/logs/dag_id=traffic_flow/run_id=scheduled__2023-02-04T00:00:00+00:00/task_id=Extract permission to 509: [Errno 1] Operation not permitted: '/opt/***/logs/dag_id=traffic_flow/run_id=scheduled__2023-02-04T00:00:00+00:00/task_id=Extract'
[2023-12-25T07:50:57.640+0000] {logging_mixin.py:188} INFO - Changing /opt/***/logs/dag_id=traffic_flow/run_id=scheduled__2023-02-04T00:00:00+00:00/task_id=Extract permission to 509
[2023-12-25T07:50:57.641+0000] {logging_mixin.py:188} INFO - Failed to change /opt/***/logs/dag_id=traffic_flow/run_id=scheduled__2023-02-04T00:00:00+00:00/task_id=Extract permission to 509: [Errno 1] Operation not permitted: '/opt/***/logs/dag_id=traffic_flow/run_id=scheduled__2023-02-04T00:00:00+00:00/task_id=Extract'
[2023-12-25T07:50:57.769+0000] {taskinstance.py:1957} INFO - Dependencies all met for dep_context=non-requeueable deps ti=<TaskInstance: traffic_flow.Extract scheduled__2023-02-04T00:00:00+00:00 [queued]>
[2023-12-25T07:50:57.799+0000] {taskinstance.py:1957} INFO - Dependencies all met for dep_context=requeueable deps ti=<TaskInstance: traffic_flow.Extract scheduled__2023-02-04T00:00:00+00:00 [queued]>
[2023-12-25T07:50:57.799+0000] {taskinstance.py:2171} INFO - Starting attempt 2 of 2
[2023-12-25T07:50:57.899+0000] {taskinstance.py:2192} INFO - Executing <Task(PythonOperator): Extract> on 2023-02-04 00:00:00+00:00
[2023-12-25T07:50:57.908+0000] {standard_task_runner.py:60} INFO - Started process 682 to run task
[2023-12-25T07:50:57.917+0000] {standard_task_runner.py:87} INFO - Running: ['***', 'tasks', 'run', 'traffic_flow', 'Extract', 'scheduled__2023-02-04T00:00:00+00:00', '--job-id', '89', '--raw', '--subdir', 'DAGS_FOLDER/main.py', '--cfg-path', '/tmp/tmpf6y9csnd']
[2023-12-25T07:50:57.942+0000] {standard_task_runner.py:88} INFO - Job 89: Subtask Extract
[2023-12-25T07:50:58.014+0000] {logging_mixin.py:188} WARNING - /home/***/.local/lib/python3.8/site-packages/***/settings.py:195 DeprecationWarning: The sql_alchemy_conn option in [core] has been moved to the sql_alchemy_conn option in [database] - the old setting has been used, but please update your config.
[2023-12-25T07:50:58.111+0000] {logging_mixin.py:188} INFO - Changing /opt/***/logs/dag_id=traffic_flow/run_id=scheduled__2023-02-04T00:00:00+00:00/task_id=Extract permission to 509
[2023-12-25T07:50:58.112+0000] {logging_mixin.py:188} INFO - Failed to change /opt/***/logs/dag_id=traffic_flow/run_id=scheduled__2023-02-04T00:00:00+00:00/task_id=Extract permission to 509: [Errno 1] Operation not permitted: '/opt/***/logs/dag_id=traffic_flow/run_id=scheduled__2023-02-04T00:00:00+00:00/task_id=Extract'
[2023-12-25T07:50:58.112+0000] {task_command.py:423} INFO - Running <TaskInstance: traffic_flow.Extract scheduled__2023-02-04T00:00:00+00:00 [running]> on host b33131cfaa7f
[2023-12-25T07:50:58.737+0000] {taskinstance.py:2481} INFO - Exporting env vars: AIRFLOW_CTX_DAG_OWNER='***' AIRFLOW_CTX_DAG_ID='traffic_flow' AIRFLOW_CTX_TASK_ID='Extract' AIRFLOW_CTX_EXECUTION_DATE='2023-02-04T00:00:00+00:00' AIRFLOW_CTX_TRY_NUMBER='2' AIRFLOW_CTX_DAG_RUN_ID='scheduled__2023-02-04T00:00:00+00:00'
[2023-12-25T07:50:58.739+0000] {taskinstance.py:2699} ERROR - Task failed with exception
Traceback (most recent call last):
  File "/home/airflow/.local/lib/python3.8/site-packages/airflow/models/taskinstance.py", line 433, in _execute_task
    result = execute_callable(context=context, **execute_callable_kwargs)
  File "/home/airflow/.local/lib/python3.8/site-packages/airflow/operators/python.py", line 199, in execute
    return_value = self.execute_callable()
  File "/home/airflow/.local/lib/python3.8/site-packages/airflow/operators/python.py", line 216, in execute_callable
    return self.python_callable(*self.op_args, **self.op_kwargs)
  File "/opt/airflow/dags/main.py", line 31, in task_a_function
    csv_reader.read_data()
  File "/opt/airflow/dags/src/extract_data_source.py", line 10, in read_data
    with open(self.csv_path, 'r') as file:
FileNotFoundError: [Errno 2] No such file or directory: '/home/hp/Downloads/20181024_d1_0830_0900(2).csv'
[2023-12-25T07:50:58.799+0000] {taskinstance.py:1138} INFO - Marking task as FAILED. dag_id=traffic_flow, task_id=Extract, execution_date=20230204T000000, start_date=20231225T075057, end_date=20231225T075058
[2023-12-25T07:50:59.652+0000] {standard_task_runner.py:107} ERROR - Failed to execute job 89 for task Extract ([Errno 2] No such file or directory: '/home/hp/Downloads/20181024_d1_0830_0900(2).csv'; 682)
[2023-12-25T07:50:59.687+0000] {local_task_job_runner.py:234} INFO - Task exited with return code 1
[2023-12-25T07:51:00.045+0000] {taskinstance.py:3281} INFO - 0 downstream tasks scheduled from follow-on schedule check
